[2025-04-29T19:02:55.852+0000] {taskinstance.py:1103} INFO - Dependencies all met for dep_context=non-requeueable deps ti=<TaskInstance: superset_sync.dataset manual__2025-04-29T19:00:50.321406+00:00 [queued]>
[2025-04-29T19:02:55.857+0000] {taskinstance.py:1103} INFO - Dependencies all met for dep_context=requeueable deps ti=<TaskInstance: superset_sync.dataset manual__2025-04-29T19:00:50.321406+00:00 [queued]>
[2025-04-29T19:02:55.858+0000] {taskinstance.py:1308} INFO - Starting attempt 2 of 2
[2025-04-29T19:02:55.867+0000] {taskinstance.py:1327} INFO - Executing <Task(PythonOperator): dataset> on 2025-04-29 19:00:50.321406+00:00
[2025-04-29T19:02:55.871+0000] {standard_task_runner.py:57} INFO - Started process 2635 to run task
[2025-04-29T19:02:55.873+0000] {standard_task_runner.py:84} INFO - Running: ['airflow', 'tasks', 'run', 'superset_sync', 'dataset', 'manual__2025-04-29T19:00:50.321406+00:00', '--job-id', '104', '--raw', '--subdir', 'DAGS_FOLDER/superset_sync.py', '--cfg-path', '/tmp/tmp6v01emn2']
[2025-04-29T19:02:55.874+0000] {standard_task_runner.py:85} INFO - Job 104: Subtask dataset
[2025-04-29T19:02:55.910+0000] {task_command.py:410} INFO - Running <TaskInstance: superset_sync.dataset manual__2025-04-29T19:00:50.321406+00:00 [running]> on host 2a409c1b1489
[2025-04-29T19:02:56.048+0000] {taskinstance.py:1547} INFO - Exporting env vars: AIRFLOW_CTX_DAG_OWNER='airflow' AIRFLOW_CTX_DAG_ID='superset_sync' AIRFLOW_CTX_TASK_ID='dataset' AIRFLOW_CTX_EXECUTION_DATE='2025-04-29T19:00:50.321406+00:00' AIRFLOW_CTX_TRY_NUMBER='2' AIRFLOW_CTX_DAG_RUN_ID='manual__2025-04-29T19:00:50.321406+00:00'
[2025-04-29T19:02:56.274+0000] {taskinstance.py:1824} ERROR - Task failed with exception
Traceback (most recent call last):
  File "/home/airflow/.local/lib/python3.7/site-packages/airflow/operators/python.py", line 181, in execute
    return_value = self.execute_callable()
  File "/home/airflow/.local/lib/python3.7/site-packages/airflow/operators/python.py", line 198, in execute_callable
    return self.python_callable(*self.op_args, **self.op_kwargs)
  File "/opt/airflow/dags/superset_sync.py", line 132, in make_datasets
    head, _get_db_id(head, PG_DBNAME), PG_SCHEMA, TABLE)
  File "/opt/airflow/dags/superset_sync.py", line 105, in _ensure_dataset
    ds = _dataset_id(head, db_id, schema, table)
  File "/opt/airflow/dags/superset_sync.py", line 99, in _dataset_id
    r.raise_for_status()
  File "/home/airflow/.local/lib/python3.7/site-packages/requests/models.py", line 1021, in raise_for_status
    raise HTTPError(http_error_msg, response=self)
requests.exceptions.HTTPError: 400 Client Error: BAD REQUEST for url: http://superset:8088/api/v1/dataset/?q=%28filters%3A%21%28%28col%3Adatabase_id%2Copr%3Aeq%2Cvalue%3A1%29%2C%28col%3Aschema%2Copr%3Aeq%2Cvalue%3A%27mart%27%29%2C%28col%3Atable_name%2Copr%3Aeq%2Cvalue%3A%27suspicious_transactions%27%29%29%29
[2025-04-29T19:02:56.281+0000] {taskinstance.py:1350} INFO - Marking task as FAILED. dag_id=superset_sync, task_id=dataset, execution_date=20250429T190050, start_date=20250429T190255, end_date=20250429T190256
[2025-04-29T19:02:56.290+0000] {standard_task_runner.py:109} ERROR - Failed to execute job 104 for task dataset (400 Client Error: BAD REQUEST for url: http://superset:8088/api/v1/dataset/?q=%28filters%3A%21%28%28col%3Adatabase_id%2Copr%3Aeq%2Cvalue%3A1%29%2C%28col%3Aschema%2Copr%3Aeq%2Cvalue%3A%27mart%27%29%2C%28col%3Atable_name%2Copr%3Aeq%2Cvalue%3A%27suspicious_transactions%27%29%29%29; 2635)
[2025-04-29T19:02:56.325+0000] {local_task_job_runner.py:225} INFO - Task exited with return code 1
[2025-04-29T19:02:56.345+0000] {taskinstance.py:2653} INFO - 0 downstream tasks scheduled from follow-on schedule check
