[2025-04-30T11:46:07.214+0000] {taskinstance.py:1103} INFO - Dependencies all met for dep_context=non-requeueable deps ti=<TaskInstance: superset_sync.dataset manual__2025-04-30T11:44:01.814079+00:00 [queued]>
[2025-04-30T11:46:07.220+0000] {taskinstance.py:1103} INFO - Dependencies all met for dep_context=requeueable deps ti=<TaskInstance: superset_sync.dataset manual__2025-04-30T11:44:01.814079+00:00 [queued]>
[2025-04-30T11:46:07.220+0000] {taskinstance.py:1308} INFO - Starting attempt 2 of 2
[2025-04-30T11:46:07.231+0000] {taskinstance.py:1327} INFO - Executing <Task(PythonOperator): dataset> on 2025-04-30 11:44:01.814079+00:00
[2025-04-30T11:46:07.235+0000] {standard_task_runner.py:57} INFO - Started process 32679 to run task
[2025-04-30T11:46:07.237+0000] {standard_task_runner.py:84} INFO - Running: ['airflow', 'tasks', 'run', 'superset_sync', 'dataset', 'manual__2025-04-30T11:44:01.814079+00:00', '--job-id', '35', '--raw', '--subdir', 'DAGS_FOLDER/superset_sync.py', '--cfg-path', '/tmp/tmpzd9n5p0d']
[2025-04-30T11:46:07.238+0000] {standard_task_runner.py:85} INFO - Job 35: Subtask dataset
[2025-04-30T11:46:07.275+0000] {task_command.py:410} INFO - Running <TaskInstance: superset_sync.dataset manual__2025-04-30T11:44:01.814079+00:00 [running]> on host f349d8d6503e
[2025-04-30T11:46:07.417+0000] {taskinstance.py:1547} INFO - Exporting env vars: AIRFLOW_CTX_DAG_OWNER='airflow' AIRFLOW_CTX_DAG_ID='superset_sync' AIRFLOW_CTX_TASK_ID='dataset' AIRFLOW_CTX_EXECUTION_DATE='2025-04-30T11:44:01.814079+00:00' AIRFLOW_CTX_TRY_NUMBER='2' AIRFLOW_CTX_DAG_RUN_ID='manual__2025-04-30T11:44:01.814079+00:00'
[2025-04-30T11:46:07.697+0000] {superset_sync.py:112} INFO - Dataset mart.suspicious_transactions уже существует (id=1)
[2025-04-30T11:46:07.780+0000] {taskinstance.py:1824} ERROR - Task failed with exception
Traceback (most recent call last):
  File "/home/airflow/.local/lib/python3.7/site-packages/airflow/operators/python.py", line 181, in execute
    return_value = self.execute_callable()
  File "/home/airflow/.local/lib/python3.7/site-packages/airflow/operators/python.py", line 198, in execute_callable
    return self.python_callable(*self.op_args, **self.op_kwargs)
  File "/opt/airflow/dags/superset_sync.py", line 172, in task_datasets
    _ensure_dataset(sess, head, ch_db_id)
  File "/opt/airflow/dags/superset_sync.py", line 124, in _ensure_dataset
    raise RuntimeError(f"Ошибка создания датасета: {r.text}")
RuntimeError: Ошибка создания датасета: {"message":{"table_name":["Table [suspicious_transactions] could not be found, please double check your database connection, schema, and table name"]}}

[2025-04-30T11:46:07.787+0000] {taskinstance.py:1350} INFO - Marking task as FAILED. dag_id=superset_sync, task_id=dataset, execution_date=20250430T114401, start_date=20250430T114607, end_date=20250430T114607
[2025-04-30T11:46:07.795+0000] {standard_task_runner.py:109} ERROR - Failed to execute job 35 for task dataset (Ошибка создания датасета: {"message":{"table_name":["Table [suspicious_transactions] could not be found, please double check your database connection, schema, and table name"]}}
; 32679)
[2025-04-30T11:46:07.810+0000] {local_task_job_runner.py:225} INFO - Task exited with return code 1
[2025-04-30T11:46:07.832+0000] {taskinstance.py:2653} INFO - 0 downstream tasks scheduled from follow-on schedule check
