[2025-04-29T21:42:53.258+0000] {taskinstance.py:1103} INFO - Dependencies all met for dep_context=non-requeueable deps ti=<TaskInstance: superset_sync.dataset manual__2025-04-29T21:40:48.008204+00:00 [queued]>
[2025-04-29T21:42:53.264+0000] {taskinstance.py:1103} INFO - Dependencies all met for dep_context=requeueable deps ti=<TaskInstance: superset_sync.dataset manual__2025-04-29T21:40:48.008204+00:00 [queued]>
[2025-04-29T21:42:53.265+0000] {taskinstance.py:1308} INFO - Starting attempt 2 of 2
[2025-04-29T21:42:53.275+0000] {taskinstance.py:1327} INFO - Executing <Task(PythonOperator): dataset> on 2025-04-29 21:40:48.008204+00:00
[2025-04-29T21:42:53.278+0000] {standard_task_runner.py:57} INFO - Started process 642 to run task
[2025-04-29T21:42:53.280+0000] {standard_task_runner.py:84} INFO - Running: ['airflow', 'tasks', 'run', 'superset_sync', 'dataset', 'manual__2025-04-29T21:40:48.008204+00:00', '--job-id', '128', '--raw', '--subdir', 'DAGS_FOLDER/superset_sync.py', '--cfg-path', '/tmp/tmph63tcoc4']
[2025-04-29T21:42:53.281+0000] {standard_task_runner.py:85} INFO - Job 128: Subtask dataset
[2025-04-29T21:42:53.318+0000] {task_command.py:410} INFO - Running <TaskInstance: superset_sync.dataset manual__2025-04-29T21:40:48.008204+00:00 [running]> on host 719b7b43b976
[2025-04-29T21:42:53.458+0000] {taskinstance.py:1547} INFO - Exporting env vars: AIRFLOW_CTX_DAG_OWNER='airflow' AIRFLOW_CTX_DAG_ID='superset_sync' AIRFLOW_CTX_TASK_ID='dataset' AIRFLOW_CTX_EXECUTION_DATE='2025-04-29T21:40:48.008204+00:00' AIRFLOW_CTX_TRY_NUMBER='2' AIRFLOW_CTX_DAG_RUN_ID='manual__2025-04-29T21:40:48.008204+00:00'
[2025-04-29T21:42:53.694+0000] {taskinstance.py:1824} ERROR - Task failed with exception
Traceback (most recent call last):
  File "/home/airflow/.local/lib/python3.7/site-packages/airflow/operators/python.py", line 181, in execute
    return_value = self.execute_callable()
  File "/home/airflow/.local/lib/python3.7/site-packages/airflow/operators/python.py", line 198, in execute_callable
    return self.python_callable(*self.op_args, **self.op_kwargs)
  File "/opt/airflow/dags/superset_sync.py", line 165, in task_datasets
    pg_ds_id = _ensure_dataset(sess, head, pg_db_id)
  File "/opt/airflow/dags/superset_sync.py", line 152, in _ensure_dataset
    raise RuntimeError(f"Ошибка создания датасета: {r.text}")
RuntimeError: Ошибка создания датасета: {"errors": [{"message": "400 Bad Request: The CSRF session token is missing.", "error_type": "GENERIC_BACKEND_ERROR", "level": "error", "extra": {"issue_codes": [{"code": 1011, "message": "Issue 1011 - Superset encountered an unexpected error."}]}}]}
[2025-04-29T21:42:53.701+0000] {taskinstance.py:1350} INFO - Marking task as FAILED. dag_id=superset_sync, task_id=dataset, execution_date=20250429T214048, start_date=20250429T214253, end_date=20250429T214253
[2025-04-29T21:42:53.708+0000] {standard_task_runner.py:109} ERROR - Failed to execute job 128 for task dataset (Ошибка создания датасета: {"errors": [{"message": "400 Bad Request: The CSRF session token is missing.", "error_type": "GENERIC_BACKEND_ERROR", "level": "error", "extra": {"issue_codes": [{"code": 1011, "message": "Issue 1011 - Superset encountered an unexpected error."}]}}]}; 642)
[2025-04-29T21:42:53.733+0000] {local_task_job_runner.py:225} INFO - Task exited with return code 1
[2025-04-29T21:42:53.760+0000] {taskinstance.py:2653} INFO - 0 downstream tasks scheduled from follow-on schedule check
