[2025-04-22T21:28:46.482+0000] {taskinstance.py:1103} INFO - Dependencies all met for dep_context=non-requeueable deps ti=<TaskInstance: extract_load.generate_csv manual__2025-04-22T21:26:40.966890+00:00 [queued]>
[2025-04-22T21:28:46.487+0000] {taskinstance.py:1103} INFO - Dependencies all met for dep_context=requeueable deps ti=<TaskInstance: extract_load.generate_csv manual__2025-04-22T21:26:40.966890+00:00 [queued]>
[2025-04-22T21:28:46.487+0000] {taskinstance.py:1308} INFO - Starting attempt 2 of 2
[2025-04-22T21:28:46.497+0000] {taskinstance.py:1327} INFO - Executing <Task(PythonOperator): generate_csv> on 2025-04-22 21:26:40.966890+00:00
[2025-04-22T21:28:46.501+0000] {standard_task_runner.py:57} INFO - Started process 427 to run task
[2025-04-22T21:28:46.503+0000] {standard_task_runner.py:84} INFO - Running: ['airflow', 'tasks', 'run', 'extract_load', 'generate_csv', 'manual__2025-04-22T21:26:40.966890+00:00', '--job-id', '5', '--raw', '--subdir', 'DAGS_FOLDER/extract_load.py', '--cfg-path', '/tmp/tmpqxzhh9cc']
[2025-04-22T21:28:46.504+0000] {standard_task_runner.py:85} INFO - Job 5: Subtask generate_csv
[2025-04-22T21:28:46.541+0000] {task_command.py:410} INFO - Running <TaskInstance: extract_load.generate_csv manual__2025-04-22T21:26:40.966890+00:00 [running]> on host ee3569271e7b
[2025-04-22T21:28:46.607+0000] {taskinstance.py:1547} INFO - Exporting env vars: AIRFLOW_CTX_DAG_OWNER='finbest' AIRFLOW_CTX_DAG_ID='extract_load' AIRFLOW_CTX_TASK_ID='generate_csv' AIRFLOW_CTX_EXECUTION_DATE='2025-04-22T21:26:40.966890+00:00' AIRFLOW_CTX_TRY_NUMBER='2' AIRFLOW_CTX_DAG_RUN_ID='manual__2025-04-22T21:26:40.966890+00:00'
[2025-04-22T21:28:46.608+0000] {taskinstance.py:1824} ERROR - Task failed with exception
Traceback (most recent call last):
  File "/home/airflow/.local/lib/python3.7/site-packages/airflow/operators/python.py", line 181, in execute
    return_value = self.execute_callable()
  File "/home/airflow/.local/lib/python3.7/site-packages/airflow/operators/python.py", line 198, in execute_callable
    return self.python_callable(*self.op_args, **self.op_kwargs)
  File "/opt/airflow/dags/extract_load.py", line 20, in gen_data
    with open(DST,"w",newline='') as f:
PermissionError: [Errno 13] Permission denied: '/data/bank_transactions.csv'
[2025-04-22T21:28:46.616+0000] {taskinstance.py:1350} INFO - Marking task as FAILED. dag_id=extract_load, task_id=generate_csv, execution_date=20250422T212640, start_date=20250422T212846, end_date=20250422T212846
[2025-04-22T21:28:46.623+0000] {standard_task_runner.py:109} ERROR - Failed to execute job 5 for task generate_csv ([Errno 13] Permission denied: '/data/bank_transactions.csv'; 427)
[2025-04-22T21:28:46.635+0000] {local_task_job_runner.py:225} INFO - Task exited with return code 1
[2025-04-22T21:28:46.657+0000] {taskinstance.py:2653} INFO - 0 downstream tasks scheduled from follow-on schedule check
