[2025-04-29T22:16:31.264+0000] {taskinstance.py:1103} INFO - Dependencies all met for dep_context=non-requeueable deps ti=<TaskInstance: superset_sync.dataset manual__2025-04-29T22:11:43.557206+00:00 [queued]>
[2025-04-29T22:16:31.272+0000] {taskinstance.py:1103} INFO - Dependencies all met for dep_context=requeueable deps ti=<TaskInstance: superset_sync.dataset manual__2025-04-29T22:11:43.557206+00:00 [queued]>
[2025-04-29T22:16:31.272+0000] {taskinstance.py:1308} INFO - Starting attempt 1 of 2
[2025-04-29T22:16:31.283+0000] {taskinstance.py:1327} INFO - Executing <Task(PythonOperator): dataset> on 2025-04-29 22:11:43.557206+00:00
[2025-04-29T22:16:31.287+0000] {standard_task_runner.py:57} INFO - Started process 55 to run task
[2025-04-29T22:16:31.289+0000] {standard_task_runner.py:84} INFO - Running: ['airflow', 'tasks', 'run', 'superset_sync', 'dataset', 'manual__2025-04-29T22:11:43.557206+00:00', '--job-id', '135', '--raw', '--subdir', 'DAGS_FOLDER/superset_sync.py', '--cfg-path', '/tmp/tmpwtq9633z']
[2025-04-29T22:16:31.290+0000] {standard_task_runner.py:85} INFO - Job 135: Subtask dataset
[2025-04-29T22:16:31.330+0000] {task_command.py:410} INFO - Running <TaskInstance: superset_sync.dataset manual__2025-04-29T22:11:43.557206+00:00 [running]> on host 5b42b61a262d
[2025-04-29T22:16:31.486+0000] {taskinstance.py:1547} INFO - Exporting env vars: AIRFLOW_CTX_DAG_OWNER='airflow' AIRFLOW_CTX_DAG_ID='superset_sync' AIRFLOW_CTX_TASK_ID='dataset' AIRFLOW_CTX_EXECUTION_DATE='2025-04-29T22:11:43.557206+00:00' AIRFLOW_CTX_TRY_NUMBER='1' AIRFLOW_CTX_DAG_RUN_ID='manual__2025-04-29T22:11:43.557206+00:00'
[2025-04-29T22:16:31.489+0000] {superset_sync.py:68} INFO - Superset ещё не готов (HTTPConnectionPool(host='superset', port=8088): Max retries exceeded with url: /api/v1/security/login (Caused by NewConnectionError('<urllib3.connection.HTTPConnection object at 0x7be778198550>: Failed to establish a new connection: [Errno 111] Connection refused'))). Ждём 3 c ...
[2025-04-29T22:16:34.494+0000] {superset_sync.py:68} INFO - Superset ещё не готов (HTTPConnectionPool(host='superset', port=8088): Max retries exceeded with url: /api/v1/security/login (Caused by NewConnectionError('<urllib3.connection.HTTPConnection object at 0x7be77817bc10>: Failed to establish a new connection: [Errno 111] Connection refused'))). Ждём 3 c ...
[2025-04-29T22:16:37.498+0000] {superset_sync.py:68} INFO - Superset ещё не готов (HTTPConnectionPool(host='superset', port=8088): Max retries exceeded with url: /api/v1/security/login (Caused by NewConnectionError('<urllib3.connection.HTTPConnection object at 0x7be7781ca890>: Failed to establish a new connection: [Errno 111] Connection refused'))). Ждём 3 c ...
[2025-04-29T22:16:40.503+0000] {superset_sync.py:68} INFO - Superset ещё не готов (HTTPConnectionPool(host='superset', port=8088): Max retries exceeded with url: /api/v1/security/login (Caused by NewConnectionError('<urllib3.connection.HTTPConnection object at 0x7be77821cc90>: Failed to establish a new connection: [Errno 111] Connection refused'))). Ждём 3 c ...
[2025-04-29T22:16:43.507+0000] {superset_sync.py:68} INFO - Superset ещё не готов (HTTPConnectionPool(host='superset', port=8088): Max retries exceeded with url: /api/v1/security/login (Caused by NewConnectionError('<urllib3.connection.HTTPConnection object at 0x7be7781c2d90>: Failed to establish a new connection: [Errno 111] Connection refused'))). Ждём 3 c ...
[2025-04-29T22:16:46.511+0000] {superset_sync.py:68} INFO - Superset ещё не готов (HTTPConnectionPool(host='superset', port=8088): Max retries exceeded with url: /api/v1/security/login (Caused by NewConnectionError('<urllib3.connection.HTTPConnection object at 0x7be7781c21d0>: Failed to establish a new connection: [Errno 111] Connection refused'))). Ждём 3 c ...
[2025-04-29T22:16:49.515+0000] {superset_sync.py:68} INFO - Superset ещё не готов (HTTPConnectionPool(host='superset', port=8088): Max retries exceeded with url: /api/v1/security/login (Caused by NewConnectionError('<urllib3.connection.HTTPConnection object at 0x7be777eddfd0>: Failed to establish a new connection: [Errno -3] Temporary failure in name resolution'))). Ждём 3 c ...
[2025-04-29T22:16:52.520+0000] {superset_sync.py:68} INFO - Superset ещё не готов (HTTPConnectionPool(host='superset', port=8088): Max retries exceeded with url: /api/v1/security/login (Caused by NewConnectionError('<urllib3.connection.HTTPConnection object at 0x7be777edd050>: Failed to establish a new connection: [Errno 111] Connection refused'))). Ждём 3 c ...
[2025-04-29T22:16:55.525+0000] {superset_sync.py:68} INFO - Superset ещё не готов (HTTPConnectionPool(host='superset', port=8088): Max retries exceeded with url: /api/v1/security/login (Caused by NewConnectionError('<urllib3.connection.HTTPConnection object at 0x7be777e9a990>: Failed to establish a new connection: [Errno 111] Connection refused'))). Ждём 3 c ...
[2025-04-29T22:16:58.529+0000] {superset_sync.py:68} INFO - Superset ещё не готов (HTTPConnectionPool(host='superset', port=8088): Max retries exceeded with url: /api/v1/security/login (Caused by NewConnectionError('<urllib3.connection.HTTPConnection object at 0x7be777e9e610>: Failed to establish a new connection: [Errno -3] Temporary failure in name resolution'))). Ждём 3 c ...
[2025-04-29T22:17:01.534+0000] {superset_sync.py:68} INFO - Superset ещё не готов (HTTPConnectionPool(host='superset', port=8088): Max retries exceeded with url: /api/v1/security/login (Caused by NewConnectionError('<urllib3.connection.HTTPConnection object at 0x7be777e9e450>: Failed to establish a new connection: [Errno 111] Connection refused'))). Ждём 3 c ...
[2025-04-29T22:17:04.539+0000] {superset_sync.py:68} INFO - Superset ещё не готов (HTTPConnectionPool(host='superset', port=8088): Max retries exceeded with url: /api/v1/security/login (Caused by NewConnectionError('<urllib3.connection.HTTPConnection object at 0x7be777edd1d0>: Failed to establish a new connection: [Errno 111] Connection refused'))). Ждём 3 c ...
[2025-04-29T22:17:07.545+0000] {superset_sync.py:68} INFO - Superset ещё не готов (HTTPConnectionPool(host='superset', port=8088): Max retries exceeded with url: /api/v1/security/login (Caused by NewConnectionError('<urllib3.connection.HTTPConnection object at 0x7be77f14e250>: Failed to establish a new connection: [Errno 111] Connection refused'))). Ждём 3 c ...
[2025-04-29T22:17:10.552+0000] {superset_sync.py:68} INFO - Superset ещё не готов (HTTPConnectionPool(host='superset', port=8088): Max retries exceeded with url: /api/v1/security/login (Caused by NewConnectionError('<urllib3.connection.HTTPConnection object at 0x7be7781c2410>: Failed to establish a new connection: [Errno -3] Temporary failure in name resolution'))). Ждём 3 c ...
[2025-04-29T22:17:13.557+0000] {superset_sync.py:68} INFO - Superset ещё не готов (HTTPConnectionPool(host='superset', port=8088): Max retries exceeded with url: /api/v1/security/login (Caused by NewConnectionError('<urllib3.connection.HTTPConnection object at 0x7be7781c2610>: Failed to establish a new connection: [Errno 111] Connection refused'))). Ждём 3 c ...
[2025-04-29T22:17:16.562+0000] {superset_sync.py:68} INFO - Superset ещё не готов (HTTPConnectionPool(host='superset', port=8088): Max retries exceeded with url: /api/v1/security/login (Caused by NewConnectionError('<urllib3.connection.HTTPConnection object at 0x7be77821c8d0>: Failed to establish a new connection: [Errno 111] Connection refused'))). Ждём 3 c ...
[2025-04-29T22:17:19.570+0000] {superset_sync.py:68} INFO - Superset ещё не готов (HTTPConnectionPool(host='superset', port=8088): Max retries exceeded with url: /api/v1/security/login (Caused by NewConnectionError('<urllib3.connection.HTTPConnection object at 0x7be7781caf10>: Failed to establish a new connection: [Errno -3] Temporary failure in name resolution'))). Ждём 3 c ...
[2025-04-29T22:17:22.579+0000] {superset_sync.py:68} INFO - Superset ещё не готов (HTTPConnectionPool(host='superset', port=8088): Max retries exceeded with url: /api/v1/security/login (Caused by NewConnectionError('<urllib3.connection.HTTPConnection object at 0x7be7781ca050>: Failed to establish a new connection: [Errno -3] Temporary failure in name resolution'))). Ждём 3 c ...
[2025-04-29T22:17:25.584+0000] {superset_sync.py:68} INFO - Superset ещё не готов (HTTPConnectionPool(host='superset', port=8088): Max retries exceeded with url: /api/v1/security/login (Caused by NewConnectionError('<urllib3.connection.HTTPConnection object at 0x7be7781cac50>: Failed to establish a new connection: [Errno 111] Connection refused'))). Ждём 3 c ...
[2025-04-29T22:17:28.589+0000] {superset_sync.py:68} INFO - Superset ещё не готов (HTTPConnectionPool(host='superset', port=8088): Max retries exceeded with url: /api/v1/security/login (Caused by NewConnectionError('<urllib3.connection.HTTPConnection object at 0x7be77817b190>: Failed to establish a new connection: [Errno 111] Connection refused'))). Ждём 3 c ...
[2025-04-29T22:17:31.592+0000] {taskinstance.py:1824} ERROR - Task failed with exception
Traceback (most recent call last):
  File "/home/airflow/.local/lib/python3.7/site-packages/airflow/operators/python.py", line 181, in execute
    return_value = self.execute_callable()
  File "/home/airflow/.local/lib/python3.7/site-packages/airflow/operators/python.py", line 198, in execute_callable
    return self.python_callable(*self.op_args, **self.op_kwargs)
  File "/opt/airflow/dags/superset_sync.py", line 126, in task_datasets
    sess, head = _auth()
  File "/opt/airflow/dags/superset_sync.py", line 70, in _auth
    raise RuntimeError("Не удалось авторизоваться в Superset")
RuntimeError: Не удалось авторизоваться в Superset
[2025-04-29T22:17:31.604+0000] {taskinstance.py:1350} INFO - Marking task as UP_FOR_RETRY. dag_id=superset_sync, task_id=dataset, execution_date=20250429T221143, start_date=20250429T221631, end_date=20250429T221731
[2025-04-29T22:17:31.649+0000] {standard_task_runner.py:109} ERROR - Failed to execute job 135 for task dataset (Не удалось авторизоваться в Superset; 55)
[2025-04-29T22:17:31.669+0000] {local_task_job_runner.py:225} INFO - Task exited with return code 1
[2025-04-29T22:17:31.704+0000] {taskinstance.py:2653} INFO - 0 downstream tasks scheduled from follow-on schedule check
