[2025-04-23T07:28:50.417+0000] {taskinstance.py:1103} INFO - Dependencies all met for dep_context=non-requeueable deps ti=<TaskInstance: transform.dbt_run manual__2025-04-23T07:26:43.837186+00:00 [queued]>
[2025-04-23T07:28:50.423+0000] {taskinstance.py:1103} INFO - Dependencies all met for dep_context=requeueable deps ti=<TaskInstance: transform.dbt_run manual__2025-04-23T07:26:43.837186+00:00 [queued]>
[2025-04-23T07:28:50.424+0000] {taskinstance.py:1308} INFO - Starting attempt 2 of 2
[2025-04-23T07:28:50.434+0000] {taskinstance.py:1327} INFO - Executing <Task(PythonOperator): dbt_run> on 2025-04-23 07:26:43.837186+00:00
[2025-04-23T07:28:50.437+0000] {standard_task_runner.py:57} INFO - Started process 22948 to run task
[2025-04-23T07:28:50.439+0000] {standard_task_runner.py:84} INFO - Running: ['airflow', 'tasks', 'run', 'transform', 'dbt_run', 'manual__2025-04-23T07:26:43.837186+00:00', '--job-id', '25', '--raw', '--subdir', 'DAGS_FOLDER/transform.py', '--cfg-path', '/tmp/tmph7p_sf_c']
[2025-04-23T07:28:50.440+0000] {standard_task_runner.py:85} INFO - Job 25: Subtask dbt_run
[2025-04-23T07:28:50.478+0000] {task_command.py:410} INFO - Running <TaskInstance: transform.dbt_run manual__2025-04-23T07:26:43.837186+00:00 [running]> on host ee3569271e7b
[2025-04-23T07:28:50.550+0000] {taskinstance.py:1547} INFO - Exporting env vars: AIRFLOW_CTX_DAG_OWNER='finbest' AIRFLOW_CTX_DAG_ID='transform' AIRFLOW_CTX_TASK_ID='dbt_run' AIRFLOW_CTX_EXECUTION_DATE='2025-04-23T07:26:43.837186+00:00' AIRFLOW_CTX_TRY_NUMBER='2' AIRFLOW_CTX_DAG_RUN_ID='manual__2025-04-23T07:26:43.837186+00:00'
[2025-04-23T07:28:50.647+0000] {logging_mixin.py:150} INFO - /usr/local/bin/python: Error while finding module specification for 'dbt.cli.main' (ModuleNotFoundError: No module named 'dbt')
[2025-04-23T07:28:50.648+0000] {taskinstance.py:1824} ERROR - Task failed with exception
Traceback (most recent call last):
  File "/home/airflow/.local/lib/python3.7/site-packages/airflow/operators/python.py", line 181, in execute
    return_value = self.execute_callable()
  File "/home/airflow/.local/lib/python3.7/site-packages/airflow/operators/python.py", line 198, in execute_callable
    return self.python_callable(*self.op_args, **self.op_kwargs)
  File "/opt/airflow/dags/transform.py", line 21, in run_dbt
    raise Exception(f"dbt command failed with return code {result.returncode}")
Exception: dbt command failed with return code 1
[2025-04-23T07:28:50.740+0000] {taskinstance.py:1350} INFO - Marking task as FAILED. dag_id=transform, task_id=dbt_run, execution_date=20250423T072643, start_date=20250423T072850, end_date=20250423T072850
[2025-04-23T07:28:50.750+0000] {standard_task_runner.py:109} ERROR - Failed to execute job 25 for task dbt_run (dbt command failed with return code 1; 22948)
[2025-04-23T07:28:50.771+0000] {local_task_job_runner.py:225} INFO - Task exited with return code 1
[2025-04-23T07:28:50.815+0000] {taskinstance.py:2653} INFO - 0 downstream tasks scheduled from follow-on schedule check
