[2025-04-22T21:50:05.835+0000] {taskinstance.py:1103} INFO - Dependencies all met for dep_context=non-requeueable deps ti=<TaskInstance: transform.dbt_run manual__2025-04-22T21:50:03.479873+00:00 [queued]>
[2025-04-22T21:50:05.841+0000] {taskinstance.py:1103} INFO - Dependencies all met for dep_context=requeueable deps ti=<TaskInstance: transform.dbt_run manual__2025-04-22T21:50:03.479873+00:00 [queued]>
[2025-04-22T21:50:05.841+0000] {taskinstance.py:1308} INFO - Starting attempt 1 of 2
[2025-04-22T21:50:05.851+0000] {taskinstance.py:1327} INFO - Executing <Task(BashOperator): dbt_run> on 2025-04-22 21:50:03.479873+00:00
[2025-04-22T21:50:05.854+0000] {standard_task_runner.py:57} INFO - Started process 1420 to run task
[2025-04-22T21:50:05.856+0000] {standard_task_runner.py:84} INFO - Running: ['airflow', 'tasks', 'run', 'transform', 'dbt_run', 'manual__2025-04-22T21:50:03.479873+00:00', '--job-id', '22', '--raw', '--subdir', 'DAGS_FOLDER/transform.py', '--cfg-path', '/tmp/tmpazmvjt9n']
[2025-04-22T21:50:05.857+0000] {standard_task_runner.py:85} INFO - Job 22: Subtask dbt_run
[2025-04-22T21:50:05.893+0000] {task_command.py:410} INFO - Running <TaskInstance: transform.dbt_run manual__2025-04-22T21:50:03.479873+00:00 [running]> on host ee3569271e7b
[2025-04-22T21:50:06.028+0000] {taskinstance.py:1547} INFO - Exporting env vars: AIRFLOW_CTX_DAG_OWNER='finbest' AIRFLOW_CTX_DAG_ID='transform' AIRFLOW_CTX_TASK_ID='dbt_run' AIRFLOW_CTX_EXECUTION_DATE='2025-04-22T21:50:03.479873+00:00' AIRFLOW_CTX_TRY_NUMBER='1' AIRFLOW_CTX_DAG_RUN_ID='manual__2025-04-22T21:50:03.479873+00:00'
[2025-04-22T21:50:06.030+0000] {subprocess.py:63} INFO - Tmp dir root location: /tmp
[2025-04-22T21:50:06.030+0000] {subprocess.py:75} INFO - Running command: ['/bin/bash', '-c', 'dbt run --project-dir /dbt_project --profiles-dir /dbt_project']
[2025-04-22T21:50:06.038+0000] {subprocess.py:86} INFO - Output:
[2025-04-22T21:50:06.040+0000] {subprocess.py:93} INFO - /bin/bash: line 1: dbt: command not found
[2025-04-22T21:50:06.041+0000] {subprocess.py:97} INFO - Command exited with return code 127
[2025-04-22T21:50:06.050+0000] {taskinstance.py:1824} ERROR - Task failed with exception
Traceback (most recent call last):
  File "/home/airflow/.local/lib/python3.7/site-packages/airflow/operators/bash.py", line 211, in execute
    f"Bash command failed. The command returned a non-zero exit code {result.exit_code}."
airflow.exceptions.AirflowException: Bash command failed. The command returned a non-zero exit code 127.
[2025-04-22T21:50:06.053+0000] {taskinstance.py:1350} INFO - Marking task as UP_FOR_RETRY. dag_id=transform, task_id=dbt_run, execution_date=20250422T215003, start_date=20250422T215005, end_date=20250422T215006
[2025-04-22T21:50:06.060+0000] {standard_task_runner.py:109} ERROR - Failed to execute job 22 for task dbt_run (Bash command failed. The command returned a non-zero exit code 127.; 1420)
[2025-04-22T21:50:06.068+0000] {local_task_job_runner.py:225} INFO - Task exited with return code 1
[2025-04-22T21:50:06.088+0000] {taskinstance.py:2653} INFO - 0 downstream tasks scheduled from follow-on schedule check
