[2025-04-30T11:50:44.303+0000] {taskinstance.py:1103} INFO - Dependencies all met for dep_context=non-requeueable deps ti=<TaskInstance: superset_sync.dataset manual__2025-04-30T11:50:42.252013+00:00 [queued]>
[2025-04-30T11:50:44.310+0000] {taskinstance.py:1103} INFO - Dependencies all met for dep_context=requeueable deps ti=<TaskInstance: superset_sync.dataset manual__2025-04-30T11:50:42.252013+00:00 [queued]>
[2025-04-30T11:50:44.310+0000] {taskinstance.py:1308} INFO - Starting attempt 1 of 2
[2025-04-30T11:50:44.321+0000] {taskinstance.py:1327} INFO - Executing <Task(PythonOperator): dataset> on 2025-04-30 11:50:42.252013+00:00
[2025-04-30T11:50:44.325+0000] {standard_task_runner.py:57} INFO - Started process 33221 to run task
[2025-04-30T11:50:44.327+0000] {standard_task_runner.py:84} INFO - Running: ['airflow', 'tasks', 'run', 'superset_sync', 'dataset', 'manual__2025-04-30T11:50:42.252013+00:00', '--job-id', '38', '--raw', '--subdir', 'DAGS_FOLDER/superset_sync.py', '--cfg-path', '/tmp/tmpsj6sjg3_']
[2025-04-30T11:50:44.328+0000] {standard_task_runner.py:85} INFO - Job 38: Subtask dataset
[2025-04-30T11:50:44.364+0000] {task_command.py:410} INFO - Running <TaskInstance: superset_sync.dataset manual__2025-04-30T11:50:42.252013+00:00 [running]> on host f349d8d6503e
[2025-04-30T11:50:44.506+0000] {taskinstance.py:1547} INFO - Exporting env vars: AIRFLOW_CTX_DAG_OWNER='airflow' AIRFLOW_CTX_DAG_ID='superset_sync' AIRFLOW_CTX_TASK_ID='dataset' AIRFLOW_CTX_EXECUTION_DATE='2025-04-30T11:50:42.252013+00:00' AIRFLOW_CTX_TRY_NUMBER='1' AIRFLOW_CTX_DAG_RUN_ID='manual__2025-04-30T11:50:42.252013+00:00'
[2025-04-30T11:50:44.509+0000] {superset_sync.py:72} INFO - Superset ещё не готов (HTTPConnectionPool(host='superset', port=8088): Max retries exceeded with url: /api/v1/security/login (Caused by NewConnectionError('<urllib3.connection.HTTPConnection object at 0x77745cd37510>: Failed to establish a new connection: [Errno -3] Temporary failure in name resolution'))). Ждём 3 c ...
[2025-04-30T11:50:47.517+0000] {superset_sync.py:72} INFO - Superset ещё не готов (HTTPConnectionPool(host='superset', port=8088): Max retries exceeded with url: /api/v1/security/login (Caused by NewConnectionError('<urllib3.connection.HTTPConnection object at 0x77745cd37450>: Failed to establish a new connection: [Errno -3] Temporary failure in name resolution'))). Ждём 3 c ...
[2025-04-30T11:50:50.526+0000] {superset_sync.py:72} INFO - Superset ещё не готов (HTTPConnectionPool(host='superset', port=8088): Max retries exceeded with url: /api/v1/security/login (Caused by NewConnectionError('<urllib3.connection.HTTPConnection object at 0x77745cd373d0>: Failed to establish a new connection: [Errno -3] Temporary failure in name resolution'))). Ждём 3 c ...
[2025-04-30T11:50:53.535+0000] {superset_sync.py:72} INFO - Superset ещё не готов (HTTPConnectionPool(host='superset', port=8088): Max retries exceeded with url: /api/v1/security/login (Caused by NewConnectionError('<urllib3.connection.HTTPConnection object at 0x77745cd37450>: Failed to establish a new connection: [Errno -3] Temporary failure in name resolution'))). Ждём 3 c ...
[2025-04-30T11:50:56.544+0000] {superset_sync.py:72} INFO - Superset ещё не готов (HTTPConnectionPool(host='superset', port=8088): Max retries exceeded with url: /api/v1/security/login (Caused by NewConnectionError('<urllib3.connection.HTTPConnection object at 0x77745cd37410>: Failed to establish a new connection: [Errno -3] Temporary failure in name resolution'))). Ждём 3 c ...
[2025-04-30T11:50:59.552+0000] {superset_sync.py:72} INFO - Superset ещё не готов (HTTPConnectionPool(host='superset', port=8088): Max retries exceeded with url: /api/v1/security/login (Caused by NewConnectionError('<urllib3.connection.HTTPConnection object at 0x77745cd37050>: Failed to establish a new connection: [Errno -3] Temporary failure in name resolution'))). Ждём 3 c ...
[2025-04-30T11:51:02.560+0000] {superset_sync.py:72} INFO - Superset ещё не готов (HTTPConnectionPool(host='superset', port=8088): Max retries exceeded with url: /api/v1/security/login (Caused by NewConnectionError('<urllib3.connection.HTTPConnection object at 0x77745cd373d0>: Failed to establish a new connection: [Errno -3] Temporary failure in name resolution'))). Ждём 3 c ...
[2025-04-30T11:51:05.569+0000] {superset_sync.py:72} INFO - Superset ещё не готов (HTTPConnectionPool(host='superset', port=8088): Max retries exceeded with url: /api/v1/security/login (Caused by NewConnectionError('<urllib3.connection.HTTPConnection object at 0x77745cd376d0>: Failed to establish a new connection: [Errno -3] Temporary failure in name resolution'))). Ждём 3 c ...
[2025-04-30T11:51:08.578+0000] {superset_sync.py:72} INFO - Superset ещё не готов (HTTPConnectionPool(host='superset', port=8088): Max retries exceeded with url: /api/v1/security/login (Caused by NewConnectionError('<urllib3.connection.HTTPConnection object at 0x77745cd37410>: Failed to establish a new connection: [Errno -3] Temporary failure in name resolution'))). Ждём 3 c ...
[2025-04-30T11:51:11.589+0000] {superset_sync.py:72} INFO - Superset ещё не готов (HTTPConnectionPool(host='superset', port=8088): Max retries exceeded with url: /api/v1/security/login (Caused by NewConnectionError('<urllib3.connection.HTTPConnection object at 0x77745cd37690>: Failed to establish a new connection: [Errno -3] Temporary failure in name resolution'))). Ждём 3 c ...
[2025-04-30T11:51:14.597+0000] {superset_sync.py:72} INFO - Superset ещё не готов (HTTPConnectionPool(host='superset', port=8088): Max retries exceeded with url: /api/v1/security/login (Caused by NewConnectionError('<urllib3.connection.HTTPConnection object at 0x77745cd373d0>: Failed to establish a new connection: [Errno -3] Temporary failure in name resolution'))). Ждём 3 c ...
[2025-04-30T11:51:17.607+0000] {superset_sync.py:72} INFO - Superset ещё не готов (HTTPConnectionPool(host='superset', port=8088): Max retries exceeded with url: /api/v1/security/login (Caused by NewConnectionError('<urllib3.connection.HTTPConnection object at 0x77745cd37290>: Failed to establish a new connection: [Errno -3] Temporary failure in name resolution'))). Ждём 3 c ...
[2025-04-30T11:51:20.615+0000] {superset_sync.py:72} INFO - Superset ещё не готов (HTTPConnectionPool(host='superset', port=8088): Max retries exceeded with url: /api/v1/security/login (Caused by NewConnectionError('<urllib3.connection.HTTPConnection object at 0x77745cd37410>: Failed to establish a new connection: [Errno -3] Temporary failure in name resolution'))). Ждём 3 c ...
[2025-04-30T11:51:23.623+0000] {superset_sync.py:72} INFO - Superset ещё не готов (HTTPConnectionPool(host='superset', port=8088): Max retries exceeded with url: /api/v1/security/login (Caused by NewConnectionError('<urllib3.connection.HTTPConnection object at 0x77745cd37450>: Failed to establish a new connection: [Errno -3] Temporary failure in name resolution'))). Ждём 3 c ...
[2025-04-30T11:51:26.631+0000] {superset_sync.py:72} INFO - Superset ещё не готов (HTTPConnectionPool(host='superset', port=8088): Max retries exceeded with url: /api/v1/security/login (Caused by NewConnectionError('<urllib3.connection.HTTPConnection object at 0x77745cd373d0>: Failed to establish a new connection: [Errno -3] Temporary failure in name resolution'))). Ждём 3 c ...
[2025-04-30T11:51:29.639+0000] {superset_sync.py:72} INFO - Superset ещё не готов (HTTPConnectionPool(host='superset', port=8088): Max retries exceeded with url: /api/v1/security/login (Caused by NewConnectionError('<urllib3.connection.HTTPConnection object at 0x77745cd37050>: Failed to establish a new connection: [Errno -3] Temporary failure in name resolution'))). Ждём 3 c ...
[2025-04-30T11:51:32.647+0000] {superset_sync.py:72} INFO - Superset ещё не готов (HTTPConnectionPool(host='superset', port=8088): Max retries exceeded with url: /api/v1/security/login (Caused by NewConnectionError('<urllib3.connection.HTTPConnection object at 0x77745cd37410>: Failed to establish a new connection: [Errno -3] Temporary failure in name resolution'))). Ждём 3 c ...
[2025-04-30T11:51:35.656+0000] {superset_sync.py:72} INFO - Superset ещё не готов (HTTPConnectionPool(host='superset', port=8088): Max retries exceeded with url: /api/v1/security/login (Caused by NewConnectionError('<urllib3.connection.HTTPConnection object at 0x77745cd376d0>: Failed to establish a new connection: [Errno -3] Temporary failure in name resolution'))). Ждём 3 c ...
[2025-04-30T11:51:38.665+0000] {superset_sync.py:72} INFO - Superset ещё не готов (HTTPConnectionPool(host='superset', port=8088): Max retries exceeded with url: /api/v1/security/login (Caused by NewConnectionError('<urllib3.connection.HTTPConnection object at 0x77745cd373d0>: Failed to establish a new connection: [Errno -3] Temporary failure in name resolution'))). Ждём 3 c ...
[2025-04-30T11:51:41.674+0000] {superset_sync.py:72} INFO - Superset ещё не готов (HTTPConnectionPool(host='superset', port=8088): Max retries exceeded with url: /api/v1/security/login (Caused by NewConnectionError('<urllib3.connection.HTTPConnection object at 0x77745cd37690>: Failed to establish a new connection: [Errno -3] Temporary failure in name resolution'))). Ждём 3 c ...
[2025-04-30T11:51:44.678+0000] {taskinstance.py:1824} ERROR - Task failed with exception
Traceback (most recent call last):
  File "/home/airflow/.local/lib/python3.7/site-packages/airflow/operators/python.py", line 181, in execute
    return_value = self.execute_callable()
  File "/home/airflow/.local/lib/python3.7/site-packages/airflow/operators/python.py", line 198, in execute_callable
    return self.python_callable(*self.op_args, **self.op_kwargs)
  File "/opt/airflow/dags/superset_sync.py", line 165, in task_datasets
    sess, head = _auth()
  File "/opt/airflow/dags/superset_sync.py", line 74, in _auth
    raise RuntimeError("Не удалось авторизоваться в Superset")
RuntimeError: Не удалось авторизоваться в Superset
[2025-04-30T11:51:44.696+0000] {taskinstance.py:1350} INFO - Marking task as UP_FOR_RETRY. dag_id=superset_sync, task_id=dataset, execution_date=20250430T115042, start_date=20250430T115044, end_date=20250430T115144
[2025-04-30T11:51:44.715+0000] {standard_task_runner.py:109} ERROR - Failed to execute job 38 for task dataset (Не удалось авторизоваться в Superset; 33221)
[2025-04-30T11:51:44.758+0000] {local_task_job_runner.py:225} INFO - Task exited with return code 1
[2025-04-30T11:51:44.790+0000] {taskinstance.py:2653} INFO - 0 downstream tasks scheduled from follow-on schedule check
