[2025-04-27T16:43:12.432+0000] {taskinstance.py:1103} INFO - Dependencies all met for dep_context=non-requeueable deps ti=<TaskInstance: superset_sync.dataset manual__2025-04-27T16:43:09.715504+00:00 [queued]>
[2025-04-27T16:43:12.438+0000] {taskinstance.py:1103} INFO - Dependencies all met for dep_context=requeueable deps ti=<TaskInstance: superset_sync.dataset manual__2025-04-27T16:43:09.715504+00:00 [queued]>
[2025-04-27T16:43:12.439+0000] {taskinstance.py:1308} INFO - Starting attempt 1 of 1
[2025-04-27T16:43:12.448+0000] {taskinstance.py:1327} INFO - Executing <Task(PythonOperator): dataset> on 2025-04-27 16:43:09.715504+00:00
[2025-04-27T16:43:12.451+0000] {standard_task_runner.py:57} INFO - Started process 550 to run task
[2025-04-27T16:43:12.453+0000] {standard_task_runner.py:84} INFO - Running: ['airflow', 'tasks', 'run', 'superset_sync', 'dataset', 'manual__2025-04-27T16:43:09.715504+00:00', '--job-id', '10', '--raw', '--subdir', 'DAGS_FOLDER/superset_sync.py', '--cfg-path', '/tmp/tmpepdzv1uc']
[2025-04-27T16:43:12.454+0000] {standard_task_runner.py:85} INFO - Job 10: Subtask dataset
[2025-04-27T16:43:12.491+0000] {task_command.py:410} INFO - Running <TaskInstance: superset_sync.dataset manual__2025-04-27T16:43:09.715504+00:00 [running]> on host 3df9164c4a1b
[2025-04-27T16:43:12.627+0000] {taskinstance.py:1547} INFO - Exporting env vars: AIRFLOW_CTX_DAG_OWNER='airflow' AIRFLOW_CTX_DAG_ID='superset_sync' AIRFLOW_CTX_TASK_ID='dataset' AIRFLOW_CTX_EXECUTION_DATE='2025-04-27T16:43:09.715504+00:00' AIRFLOW_CTX_TRY_NUMBER='1' AIRFLOW_CTX_DAG_RUN_ID='manual__2025-04-27T16:43:09.715504+00:00'
[2025-04-27T16:43:12.630+0000] {taskinstance.py:1824} ERROR - Task failed with exception
Traceback (most recent call last):
  File "/home/airflow/.local/lib/python3.7/site-packages/urllib3/connection.py", line 175, in _new_conn
    (self._dns_host, self.port), self.timeout, **extra_kw
  File "/home/airflow/.local/lib/python3.7/site-packages/urllib3/util/connection.py", line 72, in create_connection
    for res in socket.getaddrinfo(host, port, family, socket.SOCK_STREAM):
  File "/usr/local/lib/python3.7/socket.py", line 752, in getaddrinfo
    for res in _socket.getaddrinfo(host, port, family, type, proto, flags):
socket.gaierror: [Errno -3] Temporary failure in name resolution

During handling of the above exception, another exception occurred:

Traceback (most recent call last):
  File "/home/airflow/.local/lib/python3.7/site-packages/urllib3/connectionpool.py", line 721, in urlopen
    chunked=chunked,
  File "/home/airflow/.local/lib/python3.7/site-packages/urllib3/connectionpool.py", line 415, in _make_request
    conn.request(method, url, **httplib_request_kw)
  File "/home/airflow/.local/lib/python3.7/site-packages/urllib3/connection.py", line 244, in request
    super(HTTPConnection, self).request(method, url, body=body, headers=headers)
  File "/usr/local/lib/python3.7/http/client.py", line 1281, in request
    self._send_request(method, url, body, headers, encode_chunked)
  File "/usr/local/lib/python3.7/http/client.py", line 1327, in _send_request
    self.endheaders(body, encode_chunked=encode_chunked)
  File "/usr/local/lib/python3.7/http/client.py", line 1276, in endheaders
    self._send_output(message_body, encode_chunked=encode_chunked)
  File "/usr/local/lib/python3.7/http/client.py", line 1036, in _send_output
    self.send(msg)
  File "/usr/local/lib/python3.7/http/client.py", line 976, in send
    self.connect()
  File "/home/airflow/.local/lib/python3.7/site-packages/urllib3/connection.py", line 205, in connect
    conn = self._new_conn()
  File "/home/airflow/.local/lib/python3.7/site-packages/urllib3/connection.py", line 187, in _new_conn
    self, "Failed to establish a new connection: %s" % e
urllib3.exceptions.NewConnectionError: <urllib3.connection.HTTPConnection object at 0x7431bf28ef50>: Failed to establish a new connection: [Errno -3] Temporary failure in name resolution

During handling of the above exception, another exception occurred:

Traceback (most recent call last):
  File "/home/airflow/.local/lib/python3.7/site-packages/requests/adapters.py", line 497, in send
    chunked=chunked,
  File "/home/airflow/.local/lib/python3.7/site-packages/urllib3/connectionpool.py", line 799, in urlopen
    method, url, error=e, _pool=self, _stacktrace=sys.exc_info()[2]
  File "/home/airflow/.local/lib/python3.7/site-packages/urllib3/util/retry.py", line 592, in increment
    raise MaxRetryError(_pool, url, error or ResponseError(cause))
urllib3.exceptions.MaxRetryError: HTTPConnectionPool(host='superset', port=8088): Max retries exceeded with url: /api/v1/security/login (Caused by NewConnectionError('<urllib3.connection.HTTPConnection object at 0x7431bf28ef50>: Failed to establish a new connection: [Errno -3] Temporary failure in name resolution'))

During handling of the above exception, another exception occurred:

Traceback (most recent call last):
  File "/home/airflow/.local/lib/python3.7/site-packages/airflow/operators/python.py", line 181, in execute
    return_value = self.execute_callable()
  File "/home/airflow/.local/lib/python3.7/site-packages/airflow/operators/python.py", line 198, in execute_callable
    return self.python_callable(*self.op_args, **self.op_kwargs)
  File "/opt/airflow/dags/superset_sync.py", line 45, in ensure_dataset
    token = _login()
  File "/opt/airflow/dags/superset_sync.py", line 28, in _login
    timeout=10,
  File "/home/airflow/.local/lib/python3.7/site-packages/requests/api.py", line 115, in post
    return request("post", url, data=data, json=json, **kwargs)
  File "/home/airflow/.local/lib/python3.7/site-packages/requests/api.py", line 59, in request
    return session.request(method=method, url=url, **kwargs)
  File "/home/airflow/.local/lib/python3.7/site-packages/requests/sessions.py", line 589, in request
    resp = self.send(prep, **send_kwargs)
  File "/home/airflow/.local/lib/python3.7/site-packages/requests/sessions.py", line 703, in send
    r = adapter.send(request, **kwargs)
  File "/home/airflow/.local/lib/python3.7/site-packages/requests/adapters.py", line 519, in send
    raise ConnectionError(e, request=request)
requests.exceptions.ConnectionError: HTTPConnectionPool(host='superset', port=8088): Max retries exceeded with url: /api/v1/security/login (Caused by NewConnectionError('<urllib3.connection.HTTPConnection object at 0x7431bf28ef50>: Failed to establish a new connection: [Errno -3] Temporary failure in name resolution'))
[2025-04-27T16:43:12.640+0000] {taskinstance.py:1350} INFO - Marking task as FAILED. dag_id=superset_sync, task_id=dataset, execution_date=20250427T164309, start_date=20250427T164312, end_date=20250427T164312
[2025-04-27T16:43:12.648+0000] {standard_task_runner.py:109} ERROR - Failed to execute job 10 for task dataset (HTTPConnectionPool(host='superset', port=8088): Max retries exceeded with url: /api/v1/security/login (Caused by NewConnectionError('<urllib3.connection.HTTPConnection object at 0x7431bf28ef50>: Failed to establish a new connection: [Errno -3] Temporary failure in name resolution')); 550)
[2025-04-27T16:43:12.665+0000] {local_task_job_runner.py:225} INFO - Task exited with return code 1
[2025-04-27T16:43:12.687+0000] {taskinstance.py:2653} INFO - 0 downstream tasks scheduled from follow-on schedule check
