[2025-04-29T21:26:15.293+0000] {taskinstance.py:1103} INFO - Dependencies all met for dep_context=non-requeueable deps ti=<TaskInstance: superset_sync.dataset manual__2025-04-29T21:24:08.668936+00:00 [queued]>
[2025-04-29T21:26:15.299+0000] {taskinstance.py:1103} INFO - Dependencies all met for dep_context=requeueable deps ti=<TaskInstance: superset_sync.dataset manual__2025-04-29T21:24:08.668936+00:00 [queued]>
[2025-04-29T21:26:15.299+0000] {taskinstance.py:1308} INFO - Starting attempt 2 of 2
[2025-04-29T21:26:15.309+0000] {taskinstance.py:1327} INFO - Executing <Task(PythonOperator): dataset> on 2025-04-29 21:24:08.668936+00:00
[2025-04-29T21:26:15.312+0000] {standard_task_runner.py:57} INFO - Started process 8309 to run task
[2025-04-29T21:26:15.314+0000] {standard_task_runner.py:84} INFO - Running: ['airflow', 'tasks', 'run', 'superset_sync', 'dataset', 'manual__2025-04-29T21:24:08.668936+00:00', '--job-id', '120', '--raw', '--subdir', 'DAGS_FOLDER/superset_sync.py', '--cfg-path', '/tmp/tmpf7z1oz7w']
[2025-04-29T21:26:15.315+0000] {standard_task_runner.py:85} INFO - Job 120: Subtask dataset
[2025-04-29T21:26:15.351+0000] {task_command.py:410} INFO - Running <TaskInstance: superset_sync.dataset manual__2025-04-29T21:24:08.668936+00:00 [running]> on host 2a409c1b1489
[2025-04-29T21:26:15.488+0000] {taskinstance.py:1547} INFO - Exporting env vars: AIRFLOW_CTX_DAG_OWNER='airflow' AIRFLOW_CTX_DAG_ID='superset_sync' AIRFLOW_CTX_TASK_ID='dataset' AIRFLOW_CTX_EXECUTION_DATE='2025-04-29T21:24:08.668936+00:00' AIRFLOW_CTX_TRY_NUMBER='2' AIRFLOW_CTX_DAG_RUN_ID='manual__2025-04-29T21:24:08.668936+00:00'
[2025-04-29T21:26:15.729+0000] {taskinstance.py:1824} ERROR - Task failed with exception
Traceback (most recent call last):
  File "/home/airflow/.local/lib/python3.7/site-packages/airflow/operators/python.py", line 181, in execute
    return_value = self.execute_callable()
  File "/home/airflow/.local/lib/python3.7/site-packages/airflow/operators/python.py", line 198, in execute_callable
    return self.python_callable(*self.op_args, **self.op_kwargs)
  File "/opt/airflow/dags/superset_sync.py", line 104, in task_datasets
    pg_ds = _ensure_dataset(head, _get_db_id(head, PG_DBNAME))
  File "/opt/airflow/dags/superset_sync.py", line 82, in _ensure_dataset
    ds = _dataset_id(head, db_id)
  File "/opt/airflow/dags/superset_sync.py", line 75, in _dataset_id
    params={"q": q}, headers=head, timeout=10).json()["result"]
KeyError: 'result'
[2025-04-29T21:26:15.739+0000] {taskinstance.py:1350} INFO - Marking task as FAILED. dag_id=superset_sync, task_id=dataset, execution_date=20250429T212408, start_date=20250429T212615, end_date=20250429T212615
[2025-04-29T21:26:15.750+0000] {standard_task_runner.py:109} ERROR - Failed to execute job 120 for task dataset ('result'; 8309)
[2025-04-29T21:26:15.767+0000] {local_task_job_runner.py:225} INFO - Task exited with return code 1
[2025-04-29T21:26:15.796+0000] {taskinstance.py:2653} INFO - 0 downstream tasks scheduled from follow-on schedule check
