[2025-05-04T11:19:14.417+0000] {taskinstance.py:1103} INFO - Dependencies all met for dep_context=non-requeueable deps ti=<TaskInstance: extract_load.generate_csv manual__2025-05-04T11:19:11.207839+00:00 [queued]>
[2025-05-04T11:19:14.424+0000] {taskinstance.py:1103} INFO - Dependencies all met for dep_context=requeueable deps ti=<TaskInstance: extract_load.generate_csv manual__2025-05-04T11:19:11.207839+00:00 [queued]>
[2025-05-04T11:19:14.424+0000] {taskinstance.py:1308} INFO - Starting attempt 1 of 2
[2025-05-04T11:19:14.435+0000] {taskinstance.py:1327} INFO - Executing <Task(PythonOperator): generate_csv> on 2025-05-04 11:19:11.207839+00:00
[2025-05-04T11:19:14.440+0000] {standard_task_runner.py:57} INFO - Started process 83 to run task
[2025-05-04T11:19:14.442+0000] {standard_task_runner.py:84} INFO - Running: ['airflow', 'tasks', 'run', 'extract_load', 'generate_csv', 'manual__2025-05-04T11:19:11.207839+00:00', '--job-id', '99', '--raw', '--subdir', 'DAGS_FOLDER/extract_load.py', '--cfg-path', '/tmp/tmpodyoxdc1']
[2025-05-04T11:19:14.443+0000] {standard_task_runner.py:85} INFO - Job 99: Subtask generate_csv
[2025-05-04T11:19:14.455+0000] {logging_mixin.py:150} WARNING - /home/airflow/.local/lib/python3.7/site-packages/airflow/settings.py:195 DeprecationWarning: The sql_alchemy_conn option in [core] has been moved to the sql_alchemy_conn option in [database] - the old setting has been used, but please update your config.
[2025-05-04T11:19:14.482+0000] {task_command.py:410} INFO - Running <TaskInstance: extract_load.generate_csv manual__2025-05-04T11:19:11.207839+00:00 [running]> on host dc2cd69ae098
[2025-05-04T11:19:14.553+0000] {taskinstance.py:1547} INFO - Exporting env vars: AIRFLOW_CTX_DAG_OWNER='finbest' AIRFLOW_CTX_DAG_ID='extract_load' AIRFLOW_CTX_TASK_ID='generate_csv' AIRFLOW_CTX_EXECUTION_DATE='2025-05-04T11:19:11.207839+00:00' AIRFLOW_CTX_TRY_NUMBER='1' AIRFLOW_CTX_DAG_RUN_ID='manual__2025-05-04T11:19:11.207839+00:00'
[2025-05-04T11:19:14.554+0000] {taskinstance.py:1824} ERROR - Task failed with exception
Traceback (most recent call last):
  File "/home/airflow/.local/lib/python3.7/site-packages/airflow/operators/python.py", line 181, in execute
    return_value = self.execute_callable()
  File "/home/airflow/.local/lib/python3.7/site-packages/airflow/operators/python.py", line 198, in execute_callable
    return self.python_callable(*self.op_args, **self.op_kwargs)
  File "/opt/airflow/dags/extract_load.py", line 20, in gen_data
    with open(DST,"w",newline='') as f:
PermissionError: [Errno 13] Permission denied: '/data/bank_transactions.csv'
[2025-05-04T11:19:14.562+0000] {taskinstance.py:1350} INFO - Marking task as UP_FOR_RETRY. dag_id=extract_load, task_id=generate_csv, execution_date=20250504T111911, start_date=20250504T111914, end_date=20250504T111914
[2025-05-04T11:19:14.570+0000] {standard_task_runner.py:109} ERROR - Failed to execute job 99 for task generate_csv ([Errno 13] Permission denied: '/data/bank_transactions.csv'; 83)
[2025-05-04T11:19:14.614+0000] {local_task_job_runner.py:225} INFO - Task exited with return code 1
[2025-05-04T11:19:14.656+0000] {taskinstance.py:2653} INFO - 0 downstream tasks scheduled from follow-on schedule check
