[2025-04-29T12:59:55.523+0000] {taskinstance.py:1103} INFO - Dependencies all met for dep_context=non-requeueable deps ti=<TaskInstance: superset_sync.dataset manual__2025-04-29T12:59:53.087541+00:00 [queued]>
[2025-04-29T12:59:55.529+0000] {taskinstance.py:1103} INFO - Dependencies all met for dep_context=requeueable deps ti=<TaskInstance: superset_sync.dataset manual__2025-04-29T12:59:53.087541+00:00 [queued]>
[2025-04-29T12:59:55.529+0000] {taskinstance.py:1308} INFO - Starting attempt 1 of 1
[2025-04-29T12:59:55.539+0000] {taskinstance.py:1327} INFO - Executing <Task(PythonOperator): dataset> on 2025-04-29 12:59:53.087541+00:00
[2025-04-29T12:59:55.542+0000] {standard_task_runner.py:57} INFO - Started process 1657 to run task
[2025-04-29T12:59:55.544+0000] {standard_task_runner.py:84} INFO - Running: ['airflow', 'tasks', 'run', 'superset_sync', 'dataset', 'manual__2025-04-29T12:59:53.087541+00:00', '--job-id', '18', '--raw', '--subdir', 'DAGS_FOLDER/superset_sync.py', '--cfg-path', '/tmp/tmpxwx8vqau']
[2025-04-29T12:59:55.545+0000] {standard_task_runner.py:85} INFO - Job 18: Subtask dataset
[2025-04-29T12:59:55.583+0000] {task_command.py:410} INFO - Running <TaskInstance: superset_sync.dataset manual__2025-04-29T12:59:53.087541+00:00 [running]> on host bd05f2cbfffd
[2025-04-29T12:59:55.714+0000] {taskinstance.py:1547} INFO - Exporting env vars: AIRFLOW_CTX_DAG_OWNER='airflow' AIRFLOW_CTX_DAG_ID='superset_sync' AIRFLOW_CTX_TASK_ID='dataset' AIRFLOW_CTX_EXECUTION_DATE='2025-04-29T12:59:53.087541+00:00' AIRFLOW_CTX_TRY_NUMBER='1' AIRFLOW_CTX_DAG_RUN_ID='manual__2025-04-29T12:59:53.087541+00:00'
[2025-04-29T12:59:55.933+0000] {taskinstance.py:1824} ERROR - Task failed with exception
Traceback (most recent call last):
  File "/home/airflow/.local/lib/python3.7/site-packages/airflow/operators/python.py", line 181, in execute
    return_value = self.execute_callable()
  File "/home/airflow/.local/lib/python3.7/site-packages/airflow/operators/python.py", line 198, in execute_callable
    return self.python_callable(*self.op_args, **self.op_kwargs)
  File "/opt/airflow/dags/superset_sync.py", line 99, in make_datasets
    PG_SCHEMA, TABLE)
  File "/opt/airflow/dags/superset_sync.py", line 89, in _ensure_dataset
    r.raise_for_status()
  File "/home/airflow/.local/lib/python3.7/site-packages/requests/models.py", line 1021, in raise_for_status
    raise HTTPError(http_error_msg, response=self)
requests.exceptions.HTTPError: 400 Client Error: BAD REQUEST for url: http://superset:8088/api/v1/dataset/
[2025-04-29T12:59:55.943+0000] {taskinstance.py:1350} INFO - Marking task as FAILED. dag_id=superset_sync, task_id=dataset, execution_date=20250429T125953, start_date=20250429T125955, end_date=20250429T125955
[2025-04-29T12:59:55.976+0000] {standard_task_runner.py:109} ERROR - Failed to execute job 18 for task dataset (400 Client Error: BAD REQUEST for url: http://superset:8088/api/v1/dataset/; 1657)
[2025-04-29T12:59:55.997+0000] {local_task_job_runner.py:225} INFO - Task exited with return code 1
[2025-04-29T12:59:56.019+0000] {taskinstance.py:2653} INFO - 0 downstream tasks scheduled from follow-on schedule check
