[2025-04-23T10:07:29.858+0000] {taskinstance.py:1103} INFO - Dependencies all met for dep_context=non-requeueable deps ti=<TaskInstance: transform.dbt_run manual__2025-04-23T10:07:27.818104+00:00 [queued]>
[2025-04-23T10:07:29.863+0000] {taskinstance.py:1103} INFO - Dependencies all met for dep_context=requeueable deps ti=<TaskInstance: transform.dbt_run manual__2025-04-23T10:07:27.818104+00:00 [queued]>
[2025-04-23T10:07:29.863+0000] {taskinstance.py:1308} INFO - Starting attempt 1 of 2
[2025-04-23T10:07:29.873+0000] {taskinstance.py:1327} INFO - Executing <Task(PythonOperator): dbt_run> on 2025-04-23 10:07:27.818104+00:00
[2025-04-23T10:07:29.877+0000] {standard_task_runner.py:57} INFO - Started process 221 to run task
[2025-04-23T10:07:29.879+0000] {standard_task_runner.py:84} INFO - Running: ['airflow', 'tasks', 'run', 'transform', 'dbt_run', 'manual__2025-04-23T10:07:27.818104+00:00', '--job-id', '10', '--raw', '--subdir', 'DAGS_FOLDER/transform.py', '--cfg-path', '/tmp/tmpencc3ahi']
[2025-04-23T10:07:29.880+0000] {standard_task_runner.py:85} INFO - Job 10: Subtask dbt_run
[2025-04-23T10:07:29.918+0000] {task_command.py:410} INFO - Running <TaskInstance: transform.dbt_run manual__2025-04-23T10:07:27.818104+00:00 [running]> on host 9695aa16dd97
[2025-04-23T10:07:30.048+0000] {taskinstance.py:1547} INFO - Exporting env vars: AIRFLOW_CTX_DAG_OWNER='finbest' AIRFLOW_CTX_DAG_ID='transform' AIRFLOW_CTX_TASK_ID='dbt_run' AIRFLOW_CTX_EXECUTION_DATE='2025-04-23T10:07:27.818104+00:00' AIRFLOW_CTX_TRY_NUMBER='1' AIRFLOW_CTX_DAG_RUN_ID='manual__2025-04-23T10:07:27.818104+00:00'
[2025-04-23T10:07:32.392+0000] {taskinstance.py:1824} ERROR - Task failed with exception
Traceback (most recent call last):
  File "/home/airflow/.local/lib/python3.7/site-packages/airflow/operators/python.py", line 181, in execute
    return_value = self.execute_callable()
  File "/home/airflow/.local/lib/python3.7/site-packages/airflow/operators/python.py", line 198, in execute_callable
    return self.python_callable(*self.op_args, **self.op_kwargs)
  File "/opt/airflow/dags/transform.py", line 22, in run_dbt
    raise Exception(f"dbt command failed with return code {result.returncode}")
Exception: dbt command failed with return code 2
[2025-04-23T10:07:32.402+0000] {taskinstance.py:1350} INFO - Marking task as UP_FOR_RETRY. dag_id=transform, task_id=dbt_run, execution_date=20250423T100727, start_date=20250423T100729, end_date=20250423T100732
[2025-04-23T10:07:32.412+0000] {standard_task_runner.py:109} ERROR - Failed to execute job 10 for task dbt_run (dbt command failed with return code 2; 221)
[2025-04-23T10:07:32.458+0000] {local_task_job_runner.py:225} INFO - Task exited with return code 1
[2025-04-23T10:07:32.557+0000] {taskinstance.py:2653} INFO - 0 downstream tasks scheduled from follow-on schedule check
