[2025-04-29T18:34:28.667+0000] {taskinstance.py:1103} INFO - Dependencies all met for dep_context=non-requeueable deps ti=<TaskInstance: superset_sync.dataset manual__2025-04-29T18:34:25.915759+00:00 [queued]>
[2025-04-29T18:34:28.675+0000] {taskinstance.py:1103} INFO - Dependencies all met for dep_context=requeueable deps ti=<TaskInstance: superset_sync.dataset manual__2025-04-29T18:34:25.915759+00:00 [queued]>
[2025-04-29T18:34:28.675+0000] {taskinstance.py:1308} INFO - Starting attempt 1 of 1
[2025-04-29T18:34:28.686+0000] {taskinstance.py:1327} INFO - Executing <Task(PythonOperator): dataset> on 2025-04-29 18:34:25.915759+00:00
[2025-04-29T18:34:28.689+0000] {standard_task_runner.py:57} INFO - Started process 1493 to run task
[2025-04-29T18:34:28.691+0000] {standard_task_runner.py:84} INFO - Running: ['airflow', 'tasks', 'run', 'superset_sync', 'dataset', 'manual__2025-04-29T18:34:25.915759+00:00', '--job-id', '101', '--raw', '--subdir', 'DAGS_FOLDER/superset_sync.py', '--cfg-path', '/tmp/tmpy29sp_h0']
[2025-04-29T18:34:28.693+0000] {standard_task_runner.py:85} INFO - Job 101: Subtask dataset
[2025-04-29T18:34:28.731+0000] {task_command.py:410} INFO - Running <TaskInstance: superset_sync.dataset manual__2025-04-29T18:34:25.915759+00:00 [running]> on host 2a409c1b1489
[2025-04-29T18:34:28.893+0000] {taskinstance.py:1547} INFO - Exporting env vars: AIRFLOW_CTX_DAG_OWNER='airflow' AIRFLOW_CTX_DAG_ID='superset_sync' AIRFLOW_CTX_TASK_ID='dataset' AIRFLOW_CTX_EXECUTION_DATE='2025-04-29T18:34:25.915759+00:00' AIRFLOW_CTX_TRY_NUMBER='1' AIRFLOW_CTX_DAG_RUN_ID='manual__2025-04-29T18:34:25.915759+00:00'
[2025-04-29T18:34:29.251+0000] {superset_sync.py:100} ERROR - Ошибка при создании датасета: 400, {"errors": [{"message": "400 Bad Request: The CSRF token is missing.", "error_type": "GENERIC_BACKEND_ERROR", "level": "error", "extra": {"issue_codes": [{"code": 1011, "message": "Issue 1011 - Superset encountered an unexpected error."}]}}]}
[2025-04-29T18:34:29.252+0000] {taskinstance.py:1824} ERROR - Task failed with exception
Traceback (most recent call last):
  File "/home/airflow/.local/lib/python3.7/site-packages/airflow/operators/python.py", line 181, in execute
    return_value = self.execute_callable()
  File "/home/airflow/.local/lib/python3.7/site-packages/airflow/operators/python.py", line 198, in execute_callable
    return self.python_callable(*self.op_args, **self.op_kwargs)
  File "/opt/airflow/dags/superset_sync.py", line 113, in make_datasets
    PG_SCHEMA, TABLE)
  File "/opt/airflow/dags/superset_sync.py", line 102, in _ensure_dataset
    r.raise_for_status()
  File "/home/airflow/.local/lib/python3.7/site-packages/requests/models.py", line 1021, in raise_for_status
    raise HTTPError(http_error_msg, response=self)
requests.exceptions.HTTPError: 400 Client Error: BAD REQUEST for url: http://superset:8088/api/v1/dataset/
[2025-04-29T18:34:29.259+0000] {taskinstance.py:1350} INFO - Marking task as FAILED. dag_id=superset_sync, task_id=dataset, execution_date=20250429T183425, start_date=20250429T183428, end_date=20250429T183429
[2025-04-29T18:34:29.268+0000] {standard_task_runner.py:109} ERROR - Failed to execute job 101 for task dataset (400 Client Error: BAD REQUEST for url: http://superset:8088/api/v1/dataset/; 1493)
[2025-04-29T18:34:29.304+0000] {local_task_job_runner.py:225} INFO - Task exited with return code 1
[2025-04-29T18:34:29.333+0000] {taskinstance.py:2653} INFO - 0 downstream tasks scheduled from follow-on schedule check
